const catchAsync = require('../utilities/catchAsync');
const AppError = require('../utilities/appError');

exports.deleteOne = (Model) =>
  catchAsync(async (req, res, next) => {
    const document = await Model.findByIdAndDelete(req.params.id);

    if (!document) {
      //create an error and pass it to next, as soon as next recieves a value it will assume it is a error
      return next(new AppError('No document found with that ID', 404));
    }

    res.status(204).json({
      status: 'success',
      data: null,
    });
  });
